Workbook
Name 切片器_项目名1: #N/A

Sheet 数据表（勿修改）
A1: 年份 | B1: 月份 | C1: 项目名 | D1: 临停收入 | E1: 总收入 | F1: 车位数 | G1: 收费标准 | H1: 测算项目预测收入
A2: 2022 | B2: 1 | C2: 彩诗（公共+办公） | D2: 115976 | E2: 343526 | F2: 181 | G2: 4 | H2: =E2/F2/G2*项目看板!$C$38*项目看板!$E$38*项目看板!$G$38 -> 755377.61
A3: 2022 | B3: 2 | C3: 彩诗（公共+办公） | D3: 163640 | E3: 409588 | F3: 181 | G3: 4 | H3: =E3/F3/G3*项目看板!$C$38*项目看板!$E$38*项目看板!$G$38 -> 900641.02
A4: 2022 | B4: 3 | C4: 彩诗（公共+办公） | D4: 120392 | E4: 380016 | F4: 181 | G4: 4 | H4: =E4/F4/G4*项目看板!$C$38*项目看板!$E$38*项目看板!$G$38 -> 835615.29
A5: 2022 | B5: 4 | C5: 彩诗（公共+办公） | D5: 95148 | E5: 237098 | F5: 181 | G5: 4 | H5: =E5/F5/G5*项目看板!$C$38*项目看板!$E$38*项目看板!$G$38 -> 521353.61
A6: 2022 | B6: 5 | C6: 彩诗（公共+办公） | D6: 90992 | E6: 210292 | F6: 181 | G6: 4 | H6: =E6/F6/G6*项目看板!$C$38*项目看板!$E$38*项目看板!$G$38 -> 462410.03
A7: 2022 | B7: 6 | C7: 彩诗（公共+办公） | D7: 130324 | E7: 257524 | F7: 181 | G7: 4 | H7: =E7/F7/G7*项目看板!$C$38*项目看板!$E$38*项目看板!$G$38 -> 566268.24
A8: 2022 | B8: 7 | C8: 彩诗（公共+办公） | D8: 83576 | E8: 88135.79 | F8: 181 | G8: 4 | H8: =E8/F8/G8*项目看板!$C$38*项目看板!$E$38*项目看板!$G$38 -> 193801.35
A9: 2022 | B9: 8 | C9: 彩诗（公共+办公） | D9: 95972 | E9: 152378.04 | F9: 181 | G9: 4 | H9: =E9/F9/G9*项目看板!$C$38*项目看板!$E$38*项目看板!$G$38 -> 335063.31
A10: 2022 | B10: 9 | C10: 彩诗（公共+办公） | D10: 108712 | E10: 297813.94 | F10: 181 | G10: 4 | H10: =E10/F10/G10*项目看板!$C$38*项目看板!$E$38*项目看板!$G$38 -> 654861.59
A11: 2022 | B11: 10 | C11: 彩诗（公共+办公） | D11: 105428 | E11: 304473.37 | F11: 181 | G11: 4 | H11: =E11/F11/G11*项目看板!$C$38*项目看板!$E$38*项目看板!$G$38 -> 669504.98
A12: 2022 | B12: 11 | C12: 彩诗（公共+办公） | D12: 112848 | E12: 285404.14 | F12: 181 | G12: 4 | H12: =E12/F12/G12*项目看板!$C$38*项目看板!$E$38*项目看板!$G$38 -> 627573.74
A13: 2022 | B13: 12 | C13: 彩诗（公共+办公） | D13: 101956 | E13: 261780.17 | F13: 181 | G13: 4 | H13: =E13/F13/G13*项目看板!$C$38*项目看板!$E$38*项目看板!$G$38 -> 575627.11
... A25: 2022 | B25: 12 | C25: P+R（办公+换乘） | D25: 67461.35 | E25: 121216.57 | F25: 369 | G25: 5 | H25: =E25/F25/G25*项目看板!$C$38*项目看板!$E$38*项目看板!$G$38 -> 104594.46
A26: 2022 | B26: 1 | C26: 王道公园（公共+办公） | D26: 53810 | E26: 143230 | F26: 260 | G26: 5 | H26: =E26/F26/G26*项目看板!$C$38*项目看板!$E$38*项目看板!$G$38 -> 175401.66 | I26: =SUM(H26:H37) -> 3075086.5
A27: 2022 | B27: 2 | C27: 王道公园（公共+办公） | D27: 70545 | E27: 205471 | F27: 260 | G27: 5 | H27: =E27/F27/G27*项目看板!$C$38*项目看板!$E$38*项目看板!$G$38 -> 251622.95
A28: 2022 | B28: 3 | C28: 王道公园（公共+办公） | D28: 77260 | E28: 214306 | F28: 260 | G28: 5 | H28: =E28/F28/G28*项目看板!$C$38*项目看板!$E$38*项目看板!$G$38 -> 262442.42
A29: 2022 | B29: 4 | C29: 王道公园（公共+办公） | D29: 91540 | E29: 227056 | F29: 260 | G29: 5 | H29: =E29/F29/G29*项目看板!$C$38*项目看板!$E$38*项目看板!$G$38 -> 278056.27
A30: 2022 | B30: 5 | C30: 王道公园（公共+办公） | D30: 79775 | E30: 214551 | F30: 260 | G30: 5 | H30: =E30/F30/G30*项目看板!$C$38*项目看板!$E$38*项目看板!$G$38 -> 262742.46
A31: 2022 | B31: 6 | C31: 王道公园（公共+办公） | D31: 101170 | E31: 255586 | F31: 260 | G31: 5 | H31: =E31/F31/G31*项目看板!$C$38*项目看板!$E$38*项目看板!$G$38 -> 312994.55
A32: 2022 | B32: 7 | C32: 王道公园（公共+办公） | D32: 68990 | E32: 162142.61 | F32: 260 | G32: 5 | H32: =E32/F32/G32*项目看板!$C$38*项目看板!$E$38*项目看板!$G$38 -> 198562.33
A33: 2022 | B33: 8 | C33: 王道公园（公共+办公） | D33: 97155 | E33: 195452.51 | F33: 260 | G33: 5 | H33: =E33/F33/G33*项目看板!$C$38*项目看板!$E$38*项目看板!$G$38 -> 239354.15
A34: 2022 | B34: 9 | C34: 王道公园（公共+办公） | D34: 88995 | E34: 223751.23 | F34: 260 | G34: 5 | H34: =E34/F34/G34*项目看板!$C$38*项目看板!$E$38*项目看板!$G$38 -> 274009.2
A35: 2022 | B35: 10 | C35: 王道公园（公共+办公） | D35: 74825 | E35: 203678.74 | F35: 260 | G35: 5 | H35: =E35/F35/G35*项目看板!$C$38*项目看板!$E$38*项目看板!$G$38 -> 249428.12
A36: 2022 | B36: 11 | C36: 王道公园（公共+办公） | D36: 82975 | E36: 218507.51 | F36: 260 | G36: 5 | H36: =E36/F36/G36*项目看板!$C$38*项目看板!$E$38*项目看板!$G$38 -> 267587.66
A37: 2022 | B37: 12 | C37: 王道公园（公共+办公） | D37: 82935 | E37: 247330.47 | F37: 260 | G37: 5 | H37: =E37/F37/G37*项目看板!$C$38*项目看板!$E$38*项目看板!$G$38 -> 302884.7
A38: 2022 | B38: 1 | C38: 东河路8号（医院） | D38: 214750 | E38: 215550 | F38: 170 | G38: 10 | H38: =E38/F38/G38*项目看板!$C$38*项目看板!$E$38*项目看板!$G$38 -> 201856.24
... A85: 2022 | B85: 12 | C85: 民航大厦（公共+办公） | D85: 71315 | E85: 306187.38 | F85: 205 | G85: 10 | H85: =E85/F85/G85*项目看板!$C$38*项目看板!$E$38*项目看板!$G$38 -> 237780.64
A86: 2022 | B86: 1 | C86: 安吉城市级（道路） | E86: 1530926 | F86: 3800 | G86: 10 | H86: =E86/F86/G86*项目看板!$C$38*项目看板!$E$38*项目看板!$G$38 -> 64137.742
A87: 2022 | B87: 2 | C87: 安吉城市级（道路） | E87: 1077724 | F87: 3800 | G87: 3 | H87: =E87/F87/G87*项目看板!$C$38*项目看板!$E$38*项目看板!$G$38 -> 150503.21
A88: 2022 | B88: 3 | C88: 安吉城市级（道路） | E88: 1488773 | F88: 3800 | G88: 3 | H88: =E88/F88/G88*项目看板!$C$38*项目看板!$E$38*项目看板!$G$38 -> 207905.84
A89: 2022 | B89: 4 | C89: 安吉城市级（道路） | E89: 1416774 | F89: 3800 | G89: 3 | H89: =E89/F89/G89*项目看板!$C$38*项目看板!$E$38*项目看板!$G$38 -> 197851.25
A90: 2022 | B90: 5 | C90: 安吉城市级（道路） | E90: 1764230 | F90: 3800 | G90: 3 | H90: =E90/F90/G90*项目看板!$C$38*项目看板!$E$38*项目看板!$G$38 -> 246373.17
A91: 2022 | B91: 6 | C91: 安吉城市级（道路） | E91: 1568701 | F91: 3800 | G91: 3 | H91: =E91/F91/G91*项目看板!$C$38*项目看板!$E$38*项目看板!$G$38 -> 219067.72
A92: 2022 | B92: 7 | C92: 安吉城市级（道路） | E92: 1565798 | F92: 3800 | G92: 3 | H92: =E92/F92/G92*项目看板!$C$38*项目看板!$E$38*项目看板!$G$38 -> 218662.32
A93: 2022 | B93: 8 | C93: 安吉城市级（道路） | E93: 1680725 | F93: 3800 | G93: 3 | H93: =E93/F93/G93*项目看板!$C$38*项目看板!$E$38*项目看板!$G$38 -> 234711.77
A94: 2022 | B94: 9 | C94: 安吉城市级（道路） | E94: 1478024 | F94: 3800 | G94: 3 | H94: =E94/F94/G94*项目看板!$C$38*项目看板!$E$38*项目看板!$G$38 -> 206404.76
A95: 2022 | B95: 10 | C95: 安吉城市级（道路） | E95: 1387069 | F95: 3800 | G95: 3 | H95: =E95/F95/G95*项目看板!$C$38*项目看板!$E$38*项目看板!$G$38 -> 193702.97
A96: 2022 | B96: 11 | C96: 安吉城市级（道路） | E96: 1628188 | F96: 3800 | G96: 3 | H96: =E96/F96/G96*项目看板!$C$38*项目看板!$E$38*项目看板!$G$38 -> 227375.03
A97: 2022 | B97: 12 | C97: 安吉城市级（道路） | E97: 1198605 | F97: 3800 | G97: 3 | H97: =E97/F97/G97*项目看板!$C$38*项目看板!$E$38*项目看板!$G$38 -> 167384.14
...

Sheet Sheet6
A1: 年份 | B1: 月份 | C1: 项目区域 | D1: 项目经理 | E1: 项目名 | F1: 临停收入 | G1: 代金券收入 | H1: 包月收入 | I1: 总收入 | J1: 去年总收入 | K1: 增长率
A2: 2022 | B2: 5 | C2: 杭州 | D2: 岑建强 | E2: 王道公园 | F2: 79775 | G2: 0 | H2: 134776 | I2: 214551 | J2: 187902.67 | K2: -0.12420511
A3: 2022 | B3: 5 | C3: 杭州 | D3: 刘东风 | E3: P+R | F3: 61188.01 | G3: 0 | H3: 57422 | I3: 118610.01 | J3: 170543.43 | K3: 0.43785023
A4: 2022 | B4: 5 | C4: 杭州 | D4: 刘东风 | E4: 彩诗 | F4: 90992 | G4: 300 | H4: 119000 | I4: 210292 | J4: 286265.34 | K4: 0.36127546

Sheet Sheet7
A1: 年份 | B1: 月份 | C1: 项目区域 | D1: 项目经理 | E1: 项目名 | F1: 临停收入 | G1: 代金券收入 | H1: 包月收入 | I1: 总收入 | J1: 去年总收入 | K1: 增长率
A2: 2022 | B2: 12 | C2: 杭州 | D2: 岑建强 | E2: 王道公园 | F2: 82935 | H2: 164395.47 | I2: 247330.47 | J2: 242323.4 | K2: -0.020244453
A3: 2022 | B3: 11 | C3: 杭州 | D3: 岑建强 | E3: 王道公园 | F3: 82975 | G3: 200 | H3: 135332.51 | I3: 218507.51 | J3: 212083.3 | K3: -0.029400408
A4: 2022 | B4: 10 | C4: 杭州 | D4: 岑建强 | E4: 王道公园 | F4: 74825 | G4: 0 | H4: 128853.74 | I4: 203678.74 | J4: 216218.3 | K4: 0.061565385
A5: 2022 | B5: 9 | C5: 杭州 | D5: 岑建强 | E5: 王道公园 | F5: 88995 | G5: 500 | H5: 134256.23 | I5: 223751.23 | J5: 217860 | K5: -0.026329375
A6: 2022 | B6: 8 | C6: 杭州 | D6: 岑建强 | E6: 王道公园 | F6: 97155 | G6: 1000 | H6: 97297.51 | I6: 195452.51 | J6: 222631 | K6: 0.13905419
A7: 2022 | B7: 7 | C7: 杭州 | D7: 岑建强 | E7: 王道公园 | F7: 68990 | G7: 650 | H7: 92502.61 | I7: 162142.61 | J7: 179085 | K7: 0.10449067
A8: 2022 | B8: 6 | C8: 杭州 | D8: 岑建强 | E8: 王道公园 | F8: 101170 | G8: 0 | H8: 154416 | I8: 255586 | J8: 235492.66 | K8: -0.078616747
A9: 2022 | B9: 5 | C9: 杭州 | D9: 岑建强 | E9: 王道公园 | F9: 79775 | G9: 0 | H9: 134776 | I9: 214551 | J9: 187902.67 | K9: -0.12420511
A10: 2022 | B10: 4 | C10: 杭州 | D10: 岑建强 | E10: 王道公园 | F10: 91540 | G10: 750 | H10: 134766 | I10: 227056 | J10: 199277.67 | K10: -0.12234132
A11: 2022 | B11: 3 | C11: 杭州 | D11: 岑建强 | E11: 王道公园 | F11: 77260 | G11: 0 | H11: 137046 | I11: 214306 | J11: 186397 | K11: -0.13022967
A12: 2022 | B12: 2 | C12: 杭州 | D12: 岑建强 | E12: 王道公园 | F12: 70545 | G12: 0 | H12: 134926 | I12: 205471 | J12: 155552 | K12: -0.24294913
A13: 2022 | B13: 1 | C13: 杭州 | D13: 岑建强 | E13: 王道公园 | F13: 53810 | G13: 0 | H13: 89420 | I13: 143230 | J13: 154156 | K13: 0.076282902
A14: 2022 | B14: 12 | C14: 杭州 | D14: 刘东风 | E14: P+R | F14: 67461.35 | G14: 0 | H14: 53755.22 | I14: 121216.57 | J14: 121055.8 | K14: -0.0013263038
... A28: 2022 | B28: 10 | C28: 杭州 | D28: 刘东风 | E28: 彩诗 | F28: 105428 | G28: 10000 | H28: 189045.37 | I28: 304473.37 | J28: 219653 | K28: -0.27858059
A29: 2022 | B29: 9 | C29: 杭州 | D29: 刘东风 | E29: 彩诗 | F29: 108712 | H29: 189101.94 | I29: 297813.94 | J29: 239999.26 | K29: -0.1941302
A30: 2022 | B30: 8 | C30: 杭州 | D30: 刘东风 | E30: 彩诗 | F30: 95972 | H30: 56406.04 | I30: 152378.04 | J30: 251789.34 | K30: 0.65239913
A31: 2022 | B31: 7 | C31: 杭州 | D31: 刘东风 | E31: 彩诗 | F31: 83576 | G31: 10000 | H31: -5440.21 | I31: 88135.79 | J31: 201403.34 | K31: 1.2851482
A32: 2022 | B32: 6 | C32: 杭州 | D32: 刘东风 | E32: 彩诗 | F32: 130324 | G32: 10000 | H32: 117200 | I32: 257524 | J32: 302454.34 | K32: 0.1744705
A33: 2022 | B33: 5 | C33: 杭州 | D33: 刘东风 | E33: 彩诗 | F33: 90992 | G33: 300 | H33: 119000 | I33: 210292 | J33: 286265.34 | K33: 0.36127546
A34: 2022 | B34: 4 | C34: 杭州 | D34: 刘东风 | E34: 彩诗 | F34: 95148 | H34: 141950 | I34: 237098 | J34: 279665.34 | K34: 0.17953479
A35: 2022 | B35: 3 | C35: 杭州 | D35: 刘东风 | E35: 彩诗 | F35: 120392 | G35: 1524 | H35: 258100 | I35: 380016 | J35: 284264.34 | K35: -0.25196744
A36: 2022 | B36: 2 | C36: 杭州 | D36: 刘东风 | E36: 彩诗 | F36: 163640 | G36: 21048 | H36: 224900 | I36: 409588 | J36: 307473.65 | K36: -0.24930992
A37: 2022 | B37: 1 | C37: 杭州 | D37: 刘东风 | E37: 彩诗 | F37: 115976 | G37: 10000 | H37: 217550 | I37: 343526 | J37: 204627.68 | K37: -0.40433132

Sheet Sheet8
A1: 年份 | B1: 月份 | C1: 项目区域 | D1: 项目经理 | E1: 项目名 | F1: 临停收入 | G1: 代金券收入 | H1: 包月收入 | I1: 总收入 | J1: 去年总收入 | K1: 增长率
A2: 2022 | B2: 12 | C2: 杭州 | D2: 岑建强 | E2: 王道公园 | F2: 82935 | H2: 164395.47 | I2: 247330.47 | J2: 242323.4 | K2: -0.020244453
A3: 2022 | B3: 11 | C3: 杭州 | D3: 岑建强 | E3: 王道公园 | F3: 82975 | G3: 200 | H3: 135332.51 | I3: 218507.51 | J3: 212083.3 | K3: -0.029400408
A4: 2022 | B4: 10 | C4: 杭州 | D4: 岑建强 | E4: 王道公园 | F4: 74825 | G4: 0 | H4: 128853.74 | I4: 203678.74 | J4: 216218.3 | K4: 0.061565385
A5: 2022 | B5: 9 | C5: 杭州 | D5: 岑建强 | E5: 王道公园 | F5: 88995 | G5: 500 | H5: 134256.23 | I5: 223751.23 | J5: 217860 | K5: -0.026329375
A6: 2022 | B6: 8 | C6: 杭州 | D6: 岑建强 | E6: 王道公园 | F6: 97155 | G6: 1000 | H6: 97297.51 | I6: 195452.51 | J6: 222631 | K6: 0.13905419
A7: 2022 | B7: 7 | C7: 杭州 | D7: 岑建强 | E7: 王道公园 | F7: 68990 | G7: 650 | H7: 92502.61 | I7: 162142.61 | J7: 179085 | K7: 0.10449067
A8: 2022 | B8: 6 | C8: 杭州 | D8: 岑建强 | E8: 王道公园 | F8: 101170 | G8: 0 | H8: 154416 | I8: 255586 | J8: 235492.66 | K8: -0.078616747
A9: 2022 | B9: 5 | C9: 杭州 | D9: 岑建强 | E9: 王道公园 | F9: 79775 | G9: 0 | H9: 134776 | I9: 214551 | J9: 187902.67 | K9: -0.12420511
A10: 2022 | B10: 4 | C10: 杭州 | D10: 岑建强 | E10: 王道公园 | F10: 91540 | G10: 750 | H10: 134766 | I10: 227056 | J10: 199277.67 | K10: -0.12234132
A11: 2022 | B11: 3 | C11: 杭州 | D11: 岑建强 | E11: 王道公园 | F11: 77260 | G11: 0 | H11: 137046 | I11: 214306 | J11: 186397 | K11: -0.13022967
A12: 2022 | B12: 2 | C12: 杭州 | D12: 岑建强 | E12: 王道公园 | F12: 70545 | G12: 0 | H12: 134926 | I12: 205471 | J12: 155552 | K12: -0.24294913
A13: 2022 | B13: 1 | C13: 杭州 | D13: 岑建强 | E13: 王道公园 | F13: 53810 | G13: 0 | H13: 89420 | I13: 143230 | J13: 154156 | K13: 0.076282902
A14: 2022 | B14: 12 | C14: 杭州 | D14: 刘东风 | E14: P+R | F14: 67461.35 | G14: 0 | H14: 53755.22 | I14: 121216.57 | J14: 121055.8 | K14: -0.0013263038
... A28: 2022 | B28: 10 | C28: 杭州 | D28: 刘东风 | E28: 彩诗 | F28: 105428 | G28: 10000 | H28: 189045.37 | I28: 304473.37 | J28: 219653 | K28: -0.27858059
A29: 2022 | B29: 9 | C29: 杭州 | D29: 刘东风 | E29: 彩诗 | F29: 108712 | H29: 189101.94 | I29: 297813.94 | J29: 239999.26 | K29: -0.1941302
A30: 2022 | B30: 8 | C30: 杭州 | D30: 刘东风 | E30: 彩诗 | F30: 95972 | H30: 56406.04 | I30: 152378.04 | J30: 251789.34 | K30: 0.65239913
A31: 2022 | B31: 7 | C31: 杭州 | D31: 刘东风 | E31: 彩诗 | F31: 83576 | G31: 10000 | H31: -5440.21 | I31: 88135.79 | J31: 201403.34 | K31: 1.2851482
A32: 2022 | B32: 6 | C32: 杭州 | D32: 刘东风 | E32: 彩诗 | F32: 130324 | G32: 10000 | H32: 117200 | I32: 257524 | J32: 302454.34 | K32: 0.1744705
A33: 2022 | B33: 5 | C33: 杭州 | D33: 刘东风 | E33: 彩诗 | F33: 90992 | G33: 300 | H33: 119000 | I33: 210292 | J33: 286265.34 | K33: 0.36127546
A34: 2022 | B34: 4 | C34: 杭州 | D34: 刘东风 | E34: 彩诗 | F34: 95148 | H34: 141950 | I34: 237098 | J34: 279665.34 | K34: 0.17953479
A35: 2022 | B35: 3 | C35: 杭州 | D35: 刘东风 | E35: 彩诗 | F35: 120392 | G35: 1524 | H35: 258100 | I35: 380016 | J35: 284264.34 | K35: -0.25196744
A36: 2022 | B36: 2 | C36: 杭州 | D36: 刘东风 | E36: 彩诗 | F36: 163640 | G36: 21048 | H36: 224900 | I36: 409588 | J36: 307473.65 | K36: -0.24930992
A37: 2022 | B37: 1 | C37: 杭州 | D37: 刘东风 | E37: 彩诗 | F37: 115976 | G37: 10000 | H37: 217550 | I37: 343526 | J37: 204627.68 | K37: -0.40433132

Sheet Sheet9
A1: 年份 | B1: 月份 | C1: 项目区域 | D1: 项目经理 | E1: 项目名 | F1: 临停收入 | G1: 代金券收入 | H1: 包月收入 | I1: 总收入 | J1: 去年总收入 | K1: 增长率
A2: 2022 | B2: 12 | C2: 杭州 | D2: 岑建强 | E2: 王道公园 | F2: 82935 | H2: 164395.47 | I2: 247330.47 | J2: 242323.4 | K2: -0.020244453
A3: 2022 | B3: 11 | C3: 杭州 | D3: 岑建强 | E3: 王道公园 | F3: 82975 | G3: 200 | H3: 135332.51 | I3: 218507.51 | J3: 212083.3 | K3: -0.029400408
A4: 2022 | B4: 10 | C4: 杭州 | D4: 岑建强 | E4: 王道公园 | F4: 74825 | G4: 0 | H4: 128853.74 | I4: 203678.74 | J4: 216218.3 | K4: 0.061565385
A5: 2022 | B5: 9 | C5: 杭州 | D5: 岑建强 | E5: 王道公园 | F5: 88995 | G5: 500 | H5: 134256.23 | I5: 223751.23 | J5: 217860 | K5: -0.026329375
A6: 2022 | B6: 8 | C6: 杭州 | D6: 岑建强 | E6: 王道公园 | F6: 97155 | G6: 1000 | H6: 97297.51 | I6: 195452.51 | J6: 222631 | K6: 0.13905419
A7: 2022 | B7: 7 | C7: 杭州 | D7: 岑建强 | E7: 王道公园 | F7: 68990 | G7: 650 | H7: 92502.61 | I7: 162142.61 | J7: 179085 | K7: 0.10449067
A8: 2022 | B8: 6 | C8: 杭州 | D8: 岑建强 | E8: 王道公园 | F8: 101170 | G8: 0 | H8: 154416 | I8: 255586 | J8: 235492.66 | K8: -0.078616747
A9: 2022 | B9: 5 | C9: 杭州 | D9: 岑建强 | E9: 王道公园 | F9: 79775 | G9: 0 | H9: 134776 | I9: 214551 | J9: 187902.67 | K9: -0.12420511
A10: 2022 | B10: 4 | C10: 杭州 | D10: 岑建强 | E10: 王道公园 | F10: 91540 | G10: 750 | H10: 134766 | I10: 227056 | J10: 199277.67 | K10: -0.12234132
A11: 2022 | B11: 3 | C11: 杭州 | D11: 岑建强 | E11: 王道公园 | F11: 77260 | G11: 0 | H11: 137046 | I11: 214306 | J11: 186397 | K11: -0.13022967
A12: 2022 | B12: 2 | C12: 杭州 | D12: 岑建强 | E12: 王道公园 | F12: 70545 | G12: 0 | H12: 134926 | I12: 205471 | J12: 155552 | K12: -0.24294913
A13: 2022 | B13: 1 | C13: 杭州 | D13: 岑建强 | E13: 王道公园 | F13: 53810 | G13: 0 | H13: 89420 | I13: 143230 | J13: 154156 | K13: 0.076282902
A14: 2022 | B14: 12 | C14: 杭州 | D14: 刘东风 | E14: P+R | F14: 67461.35 | G14: 0 | H14: 53755.22 | I14: 121216.57 | J14: 121055.8 | K14: -0.0013263038
... A28: 2022 | B28: 10 | C28: 杭州 | D28: 刘东风 | E28: 彩诗 | F28: 105428 | G28: 10000 | H28: 189045.37 | I28: 304473.37 | J28: 219653 | K28: -0.27858059
A29: 2022 | B29: 9 | C29: 杭州 | D29: 刘东风 | E29: 彩诗 | F29: 108712 | H29: 189101.94 | I29: 297813.94 | J29: 239999.26 | K29: -0.1941302
A30: 2022 | B30: 8 | C30: 杭州 | D30: 刘东风 | E30: 彩诗 | F30: 95972 | H30: 56406.04 | I30: 152378.04 | J30: 251789.34 | K30: 0.65239913
A31: 2022 | B31: 7 | C31: 杭州 | D31: 刘东风 | E31: 彩诗 | F31: 83576 | G31: 10000 | H31: -5440.21 | I31: 88135.79 | J31: 201403.34 | K31: 1.2851482
A32: 2022 | B32: 6 | C32: 杭州 | D32: 刘东风 | E32: 彩诗 | F32: 130324 | G32: 10000 | H32: 117200 | I32: 257524 | J32: 302454.34 | K32: 0.1744705
A33: 2022 | B33: 5 | C33: 杭州 | D33: 刘东风 | E33: 彩诗 | F33: 90992 | G33: 300 | H33: 119000 | I33: 210292 | J33: 286265.34 | K33: 0.36127546
A34: 2022 | B34: 4 | C34: 杭州 | D34: 刘东风 | E34: 彩诗 | F34: 95148 | H34: 141950 | I34: 237098 | J34: 279665.34 | K34: 0.17953479
A35: 2022 | B35: 3 | C35: 杭州 | D35: 刘东风 | E35: 彩诗 | F35: 120392 | G35: 1524 | H35: 258100 | I35: 380016 | J35: 284264.34 | K35: -0.25196744
A36: 2022 | B36: 2 | C36: 杭州 | D36: 刘东风 | E36: 彩诗 | F36: 163640 | G36: 21048 | H36: 224900 | I36: 409588 | J36: 307473.65 | K36: -0.24930992
A37: 2022 | B37: 1 | C37: 杭州 | D37: 刘东风 | E37: 彩诗 | F37: 115976 | G37: 10000 | H37: 217550 | I37: 343526 | J37: 204627.68 | K37: -0.40433132

Sheet Sheet10
A1: 年份 | B1: 月份 | C1: 项目区域 | D1: 项目经理 | E1: 项目名 | F1: 临停收入 | G1: 代金券收入 | H1: 包月收入 | I1: 总收入 | J1: 去年总收入 | K1: 增长率
A2: 2022 | B2: 12 | C2: 杭州 | D2: 岑建强 | E2: 王道公园 | F2: 82935 | H2: 164395.47 | I2: 247330.47 | J2: 242323.4 | K2: -0.020244453
A3: 2022 | B3: 11 | C3: 杭州 | D3: 岑建强 | E3: 王道公园 | F3: 82975 | G3: 200 | H3: 135332.51 | I3: 218507.51 | J3: 212083.3 | K3: -0.029400408
A4: 2022 | B4: 10 | C4: 杭州 | D4: 岑建强 | E4: 王道公园 | F4: 74825 | G4: 0 | H4: 128853.74 | I4: 203678.74 | J4: 216218.3 | K4: 0.061565385
A5: 2022 | B5: 9 | C5: 杭州 | D5: 岑建强 | E5: 王道公园 | F5: 88995 | G5: 500 | H5: 134256.23 | I5: 223751.23 | J5: 217860 | K5: -0.026329375
A6: 2022 | B6: 8 | C6: 杭州 | D6: 岑建强 | E6: 王道公园 | F6: 97155 | G6: 1000 | H6: 97297.51 | I6: 195452.51 | J6: 222631 | K6: 0.13905419
A7: 2022 | B7: 7 | C7: 杭州 | D7: 岑建强 | E7: 王道公园 | F7: 68990 | G7: 650 | H7: 92502.61 | I7: 162142.61 | J7: 179085 | K7: 0.10449067
A8: 2022 | B8: 6 | C8: 杭州 | D8: 岑建强 | E8: 王道公园 | F8: 101170 | G8: 0 | H8: 154416 | I8: 255586 | J8: 235492.66 | K8: -0.078616747
A9: 2022 | B9: 5 | C9: 杭州 | D9: 岑建强 | E9: 王道公园 | F9: 79775 | G9: 0 | H9: 134776 | I9: 214551 | J9: 187902.67 | K9: -0.12420511
A10: 2022 | B10: 4 | C10: 杭州 | D10: 岑建强 | E10: 王道公园 | F10: 91540 | G10: 750 | H10: 134766 | I10: 227056 | J10: 199277.67 | K10: -0.12234132
A11: 2022 | B11: 3 | C11: 杭州 | D11: 岑建强 | E11: 王道公园 | F11: 77260 | G11: 0 | H11: 137046 | I11: 214306 | J11: 186397 | K11: -0.13022967
A12: 2022 | B12: 2 | C12: 杭州 | D12: 岑建强 | E12: 王道公园 | F12: 70545 | G12: 0 | H12: 134926 | I12: 205471 | J12: 155552 | K12: -0.24294913
A13: 2022 | B13: 1 | C13: 杭州 | D13: 岑建强 | E13: 王道公园 | F13: 53810 | G13: 0 | H13: 89420 | I13: 143230 | J13: 154156 | K13: 0.076282902
A14: 2022 | B14: 12 | C14: 杭州 | D14: 刘东风 | E14: P+R | F14: 67461.35 | G14: 0 | H14: 53755.22 | I14: 121216.57 | J14: 121055.8 | K14: -0.0013263038
... A28: 2022 | B28: 10 | C28: 杭州 | D28: 刘东风 | E28: 彩诗 | F28: 105428 | G28: 10000 | H28: 189045.37 | I28: 304473.37 | J28: 219653 | K28: -0.27858059
A29: 2022 | B29: 9 | C29: 杭州 | D29: 刘东风 | E29: 彩诗 | F29: 108712 | H29: 189101.94 | I29: 297813.94 | J29: 239999.26 | K29: -0.1941302
A30: 2022 | B30: 8 | C30: 杭州 | D30: 刘东风 | E30: 彩诗 | F30: 95972 | H30: 56406.04 | I30: 152378.04 | J30: 251789.34 | K30: 0.65239913
A31: 2022 | B31: 7 | C31: 杭州 | D31: 刘东风 | E31: 彩诗 | F31: 83576 | G31: 10000 | H31: -5440.21 | I31: 88135.79 | J31: 201403.34 | K31: 1.2851482
A32: 2022 | B32: 6 | C32: 杭州 | D32: 刘东风 | E32: 彩诗 | F32: 130324 | G32: 10000 | H32: 117200 | I32: 257524 | J32: 302454.34 | K32: 0.1744705
A33: 2022 | B33: 5 | C33: 杭州 | D33: 刘东风 | E33: 彩诗 | F33: 90992 | G33: 300 | H33: 119000 | I33: 210292 | J33: 286265.34 | K33: 0.36127546
A34: 2022 | B34: 4 | C34: 杭州 | D34: 刘东风 | E34: 彩诗 | F34: 95148 | H34: 141950 | I34: 237098 | J34: 279665.34 | K34: 0.17953479
A35: 2022 | B35: 3 | C35: 杭州 | D35: 刘东风 | E35: 彩诗 | F35: 120392 | G35: 1524 | H35: 258100 | I35: 380016 | J35: 284264.34 | K35: -0.25196744
A36: 2022 | B36: 2 | C36: 杭州 | D36: 刘东风 | E36: 彩诗 | F36: 163640 | G36: 21048 | H36: 224900 | I36: 409588 | J36: 307473.65 | K36: -0.24930992
A37: 2022 | B37: 1 | C37: 杭州 | D37: 刘东风 | E37: 彩诗 | F37: 115976 | G37: 10000 | H37: 217550 | I37: 343526 | J37: 204627.68 | K37: -0.40433132

Sheet Sheet11
A1: 年份 | B1: 月份 | C1: 项目区域 | D1: 项目经理 | E1: 项目名 | F1: 临停收入 | G1: 代金券收入 | H1: 包月收入 | I1: 总收入 | J1: 去年总收入 | K1: 增长率
A2: 2022 | B2: 12 | C2: 杭州 | D2: 岑建强 | E2: 王道公园 | F2: 82935 | H2: 164395.47 | I2: 247330.47 | J2: 242323.4 | K2: -0.020244453
A3: 2022 | B3: 11 | C3: 杭州 | D3: 岑建强 | E3: 王道公园 | F3: 82975 | G3: 200 | H3: 135332.51 | I3: 218507.51 | J3: 212083.3 | K3: -0.029400408
A4: 2022 | B4: 10 | C4: 杭州 | D4: 岑建强 | E4: 王道公园 | F4: 74825 | G4: 0 | H4: 128853.74 | I4: 203678.74 | J4: 216218.3 | K4: 0.061565385
A5: 2022 | B5: 9 | C5: 杭州 | D5: 岑建强 | E5: 王道公园 | F5: 88995 | G5: 500 | H5: 134256.23 | I5: 223751.23 | J5: 217860 | K5: -0.026329375
A6: 2022 | B6: 8 | C6: 杭州 | D6: 岑建强 | E6: 王道公园 | F6: 97155 | G6: 1000 | H6: 97297.51 | I6: 195452.51 | J6: 222631 | K6: 0.13905419
A7: 2022 | B7: 7 | C7: 杭州 | D7: 岑建强 | E7: 王道公园 | F7: 68990 | G7: 650 | H7: 92502.61 | I7: 162142.61 | J7: 179085 | K7: 0.10449067
A8: 2022 | B8: 6 | C8: 杭州 | D8: 岑建强 | E8: 王道公园 | F8: 101170 | G8: 0 | H8: 154416 | I8: 255586 | J8: 235492.66 | K8: -0.078616747
A9: 2022 | B9: 5 | C9: 杭州 | D9: 岑建强 | E9: 王道公园 | F9: 79775 | G9: 0 | H9: 134776 | I9: 214551 | J9: 187902.67 | K9: -0.12420511
A10: 2022 | B10: 4 | C10: 杭州 | D10: 岑建强 | E10: 王道公园 | F10: 91540 | G10: 750 | H10: 134766 | I10: 227056 | J10: 199277.67 | K10: -0.12234132
A11: 2022 | B11: 3 | C11: 杭州 | D11: 岑建强 | E11: 王道公园 | F11: 77260 | G11: 0 | H11: 137046 | I11: 214306 | J11: 186397 | K11: -0.13022967
A12: 2022 | B12: 2 | C12: 杭州 | D12: 岑建强 | E12: 王道公园 | F12: 70545 | G12: 0 | H12: 134926 | I12: 205471 | J12: 155552 | K12: -0.24294913
A13: 2022 | B13: 1 | C13: 杭州 | D13: 岑建强 | E13: 王道公园 | F13: 53810 | G13: 0 | H13: 89420 | I13: 143230 | J13: 154156 | K13: 0.076282902
A14: 2022 | B14: 12 | C14: 杭州 | D14: 刘东风 | E14: P+R | F14: 67461.35 | G14: 0 | H14: 53755.22 | I14: 121216.57 | J14: 121055.8 | K14: -0.0013263038
... A28: 2022 | B28: 10 | C28: 杭州 | D28: 刘东风 | E28: 彩诗 | F28: 105428 | G28: 10000 | H28: 189045.37 | I28: 304473.37 | J28: 219653 | K28: -0.27858059
A29: 2022 | B29: 9 | C29: 杭州 | D29: 刘东风 | E29: 彩诗 | F29: 108712 | H29: 189101.94 | I29: 297813.94 | J29: 239999.26 | K29: -0.1941302
A30: 2022 | B30: 8 | C30: 杭州 | D30: 刘东风 | E30: 彩诗 | F30: 95972 | H30: 56406.04 | I30: 152378.04 | J30: 251789.34 | K30: 0.65239913
A31: 2022 | B31: 7 | C31: 杭州 | D31: 刘东风 | E31: 彩诗 | F31: 83576 | G31: 10000 | H31: -5440.21 | I31: 88135.79 | J31: 201403.34 | K31: 1.2851482
A32: 2022 | B32: 6 | C32: 杭州 | D32: 刘东风 | E32: 彩诗 | F32: 130324 | G32: 10000 | H32: 117200 | I32: 257524 | J32: 302454.34 | K32: 0.1744705
A33: 2022 | B33: 5 | C33: 杭州 | D33: 刘东风 | E33: 彩诗 | F33: 90992 | G33: 300 | H33: 119000 | I33: 210292 | J33: 286265.34 | K33: 0.36127546
A34: 2022 | B34: 4 | C34: 杭州 | D34: 刘东风 | E34: 彩诗 | F34: 95148 | H34: 141950 | I34: 237098 | J34: 279665.34 | K34: 0.17953479
A35: 2022 | B35: 3 | C35: 杭州 | D35: 刘东风 | E35: 彩诗 | F35: 120392 | G35: 1524 | H35: 258100 | I35: 380016 | J35: 284264.34 | K35: -0.25196744
A36: 2022 | B36: 2 | C36: 杭州 | D36: 刘东风 | E36: 彩诗 | F36: 163640 | G36: 21048 | H36: 224900 | I36: 409588 | J36: 307473.65 | K36: -0.24930992
A37: 2022 | B37: 1 | C37: 杭州 | D37: 刘东风 | E37: 彩诗 | F37: 115976 | G37: 10000 | H37: 217550 | I37: 343526 | J37: 204627.68 | K37: -0.40433132

Sheet Sheet12
A1: 年份 | B1: 月份 | C1: 项目区域 | D1: 项目经理 | E1: 项目名 | F1: 临停收入 | G1: 代金券收入 | H1: 包月收入 | I1: 总收入 | J1: 去年总收入 | K1: 增长率
A2: 2022 | B2: 12 | C2: 杭州 | D2: 岑建强 | E2: 王道公园 | F2: 82935 | H2: 164395.47 | I2: 247330.47 | J2: 242323.4 | K2: -0.020244453
A3: 2022 | B3: 11 | C3: 杭州 | D3: 岑建强 | E3: 王道公园 | F3: 82975 | G3: 200 | H3: 135332.51 | I3: 218507.51 | J3: 212083.3 | K3: -0.029400408
A4: 2022 | B4: 10 | C4: 杭州 | D4: 岑建强 | E4: 王道公园 | F4: 74825 | G4: 0 | H4: 128853.74 | I4: 203678.74 | J4: 216218.3 | K4: 0.061565385
A5: 2022 | B5: 9 | C5: 杭州 | D5: 岑建强 | E5: 王道公园 | F5: 88995 | G5: 500 | H5: 134256.23 | I5: 223751.23 | J5: 217860 | K5: -0.026329375
A6: 2022 | B6: 8 | C6: 杭州 | D6: 岑建强 | E6: 王道公园 | F6: 97155 | G6: 1000 | H6: 97297.51 | I6: 195452.51 | J6: 222631 | K6: 0.13905419
A7: 2022 | B7: 7 | C7: 杭州 | D7: 岑建强 | E7: 王道公园 | F7: 68990 | G7: 650 | H7: 92502.61 | I7: 162142.61 | J7: 179085 | K7: 0.10449067
A8: 2022 | B8: 6 | C8: 杭州 | D8: 岑建强 | E8: 王道公园 | F8: 101170 | G8: 0 | H8: 154416 | I8: 255586 | J8: 235492.66 | K8: -0.078616747
A9: 2022 | B9: 5 | C9: 杭州 | D9: 岑建强 | E9: 王道公园 | F9: 79775 | G9: 0 | H9: 134776 | I9: 214551 | J9: 187902.67 | K9: -0.12420511
A10: 2022 | B10: 4 | C10: 杭州 | D10: 岑建强 | E10: 王道公园 | F10: 91540 | G10: 750 | H10: 134766 | I10: 227056 | J10: 199277.67 | K10: -0.12234132
A11: 2022 | B11: 3 | C11: 杭州 | D11: 岑建强 | E11: 王道公园 | F11: 77260 | G11: 0 | H11: 137046 | I11: 214306 | J11: 186397 | K11: -0.13022967
A12: 2022 | B12: 2 | C12: 杭州 | D12: 岑建强 | E12: 王道公园 | F12: 70545 | G12: 0 | H12: 134926 | I12: 205471 | J12: 155552 | K12: -0.24294913
A13: 2022 | B13: 1 | C13: 杭州 | D13: 岑建强 | E13: 王道公园 | F13: 53810 | G13: 0 | H13: 89420 | I13: 143230 | J13: 154156 | K13: 0.076282902
A14: 2022 | B14: 12 | C14: 杭州 | D14: 刘东风 | E14: P+R | F14: 67461.35 | G14: 0 | H14: 53755.22 | I14: 121216.57 | J14: 121055.8 | K14: -0.0013263038
... A28: 2022 | B28: 10 | C28: 杭州 | D28: 刘东风 | E28: 彩诗 | F28: 105428 | G28: 10000 | H28: 189045.37 | I28: 304473.37 | J28: 219653 | K28: -0.27858059
A29: 2022 | B29: 9 | C29: 杭州 | D29: 刘东风 | E29: 彩诗 | F29: 108712 | H29: 189101.94 | I29: 297813.94 | J29: 239999.26 | K29: -0.1941302
A30: 2022 | B30: 8 | C30: 杭州 | D30: 刘东风 | E30: 彩诗 | F30: 95972 | H30: 56406.04 | I30: 152378.04 | J30: 251789.34 | K30: 0.65239913
A31: 2022 | B31: 7 | C31: 杭州 | D31: 刘东风 | E31: 彩诗 | F31: 83576 | G31: 10000 | H31: -5440.21 | I31: 88135.79 | J31: 201403.34 | K31: 1.2851482
A32: 2022 | B32: 6 | C32: 杭州 | D32: 刘东风 | E32: 彩诗 | F32: 130324 | G32: 10000 | H32: 117200 | I32: 257524 | J32: 302454.34 | K32: 0.1744705
A33: 2022 | B33: 5 | C33: 杭州 | D33: 刘东风 | E33: 彩诗 | F33: 90992 | G33: 300 | H33: 119000 | I33: 210292 | J33: 286265.34 | K33: 0.36127546
A34: 2022 | B34: 4 | C34: 杭州 | D34: 刘东风 | E34: 彩诗 | F34: 95148 | H34: 141950 | I34: 237098 | J34: 279665.34 | K34: 0.17953479
A35: 2022 | B35: 3 | C35: 杭州 | D35: 刘东风 | E35: 彩诗 | F35: 120392 | G35: 1524 | H35: 258100 | I35: 380016 | J35: 284264.34 | K35: -0.25196744
A36: 2022 | B36: 2 | C36: 杭州 | D36: 刘东风 | E36: 彩诗 | F36: 163640 | G36: 21048 | H36: 224900 | I36: 409588 | J36: 307473.65 | K36: -0.24930992
A37: 2022 | B37: 1 | C37: 杭州 | D37: 刘东风 | E37: 彩诗 | F37: 115976 | G37: 10000 | H37: 217550 | I37: 343526 | J37: 204627.68 | K37: -0.40433132

Sheet Sheet13
A1: 年份 | B1: 月份 | C1: 项目区域 | D1: 项目经理 | E1: 项目名 | F1: 临停收入 | G1: 代金券收入 | H1: 包月收入 | I1: 总收入 | J1: 去年总收入 | K1: 增长率
A2: 2022 | B2: 12 | C2: 杭州 | D2: 岑建强 | E2: 王道公园 | F2: 82935 | H2: 164395.47 | I2: 247330.47 | J2: 242323.4 | K2: -0.020244453
A3: 2022 | B3: 11 | C3: 杭州 | D3: 岑建强 | E3: 王道公园 | F3: 82975 | G3: 200 | H3: 135332.51 | I3: 218507.51 | J3: 212083.3 | K3: -0.029400408
A4: 2022 | B4: 10 | C4: 杭州 | D4: 岑建强 | E4: 王道公园 | F4: 74825 | G4: 0 | H4: 128853.74 | I4: 203678.74 | J4: 216218.3 | K4: 0.061565385
A5: 2022 | B5: 9 | C5: 杭州 | D5: 岑建强 | E5: 王道公园 | F5: 88995 | G5: 500 | H5: 134256.23 | I5: 223751.23 | J5: 217860 | K5: -0.026329375
A6: 2022 | B6: 8 | C6: 杭州 | D6: 岑建强 | E6: 王道公园 | F6: 97155 | G6: 1000 | H6: 97297.51 | I6: 195452.51 | J6: 222631 | K6: 0.13905419
A7: 2022 | B7: 7 | C7: 杭州 | D7: 岑建强 | E7: 王道公园 | F7: 68990 | G7: 650 | H7: 92502.61 | I7: 162142.61 | J7: 179085 | K7: 0.10449067
A8: 2022 | B8: 6 | C8: 杭州 | D8: 岑建强 | E8: 王道公园 | F8: 101170 | G8: 0 | H8: 154416 | I8: 255586 | J8: 235492.66 | K8: -0.078616747
A9: 2022 | B9: 5 | C9: 杭州 | D9: 岑建强 | E9: 王道公园 | F9: 79775 | G9: 0 | H9: 134776 | I9: 214551 | J9: 187902.67 | K9: -0.12420511
A10: 2022 | B10: 4 | C10: 杭州 | D10: 岑建强 | E10: 王道公园 | F10: 91540 | G10: 750 | H10: 134766 | I10: 227056 | J10: 199277.67 | K10: -0.12234132
A11: 2022 | B11: 3 | C11: 杭州 | D11: 岑建强 | E11: 王道公园 | F11: 77260 | G11: 0 | H11: 137046 | I11: 214306 | J11: 186397 | K11: -0.13022967
A12: 2022 | B12: 2 | C12: 杭州 | D12: 岑建强 | E12: 王道公园 | F12: 70545 | G12: 0 | H12: 134926 | I12: 205471 | J12: 155552 | K12: -0.24294913
A13: 2022 | B13: 1 | C13: 杭州 | D13: 岑建强 | E13: 王道公园 | F13: 53810 | G13: 0 | H13: 89420 | I13: 143230 | J13: 154156 | K13: 0.076282902
L15: =SUM(表8[总收入]) -> 2511063.1 | M15: =SUM(表8[去年总收入]) -> 2408979
N17: =(L15-M15)/M15 -> 0.042376488

Sheet Sheet1
A1: 年份 | B1: 月份 | C1: 项目区域 | D1: 项目经理 | E1: 项目名 | F1: 临停收入 | G1: 代金券收入 | H1: 包月收入 | I1: 总收入 | J1: 去年总收入 | K1: 增长率
A2: 2022 | B2: 4 | C2: 杭州 | D2: 刘东风 | E2: P+R | F2: 59647.28 | G2: 0 | H2: 47348 | I2: 106995.28 | J2: 179143.44 | K2: 0.67431161

Sheet Sheet3
A1: 年份 | B1: 月份 | C1: 项目区域 | D1: 项目经理 | E1: 项目名 | F1: 临停收入 | G1: 代金券收入 | H1: 包月收入 | I1: 总收入 | J1: 去年总收入 | K1: 增长率
A2: 2022 | B2: 4 | C2: 杭州 | D2: 岑建强 | E2: 王道公园 | F2: 91540 | G2: 750 | H2: 134766 | I2: 227056 | J2: 199277.67 | K2: -0.12234132

Sheet Sheet4
A1: 年份 | B1: 月份 | C1: 项目区域 | D1: 项目经理 | E1: 项目名 | F1: 临停收入 | G1: 代金券收入 | H1: 包月收入 | I1: 总收入 | J1: 去年总收入 | K1: 增长率
A2: 2022 | B2: 4 | C2: 杭州 | D2: 岑建强 | E2: 王道公园 | F2: 91540 | G2: 750 | H2: 134766 | I2: 227056 | J2: 199277.67 | K2: -0.12234132

Sheet Sheet14
A1: 年份 | B1: 月份 | C1: 项目区域 | D1: 项目经理 | E1: 项目名 | F1: 临停收入 | G1: 代金券收入 | H1: 包月收入 | I1: 总收入 | J1: 去年总收入 | K1: 增长率

Sheet Sheet15
A1: 年份 | B1: 月份 | C1: 项目名 | D1: 临停收入 | E1: 总收入 | F1: 车位数 | G1: 收费标准 | H1: 预测收入
A2: 2022 | B2: 1 | C2: 彩诗 | D2: 115976 | E2: 343526 | F2: 100 | G2: 5 | H2: 274820.8
A3: 2022 | B3: 2 | C3: 彩诗 | D3: 163640 | E3: 409588 | F3: 100 | G3: 5 | H3: 327670.4
A4: 2022 | B4: 3 | C4: 彩诗 | D4: 120392 | E4: 380016 | F4: 100 | G4: 5 | H4: 304012.8
A5: 2022 | B5: 4 | C5: 彩诗 | D5: 95148 | E5: 237098 | F5: 100 | G5: 5 | H5: 189678.4
A6: 2022 | B6: 5 | C6: 彩诗 | D6: 90992 | E6: 210292 | F6: 100 | G6: 5 | H6: 168233.6
A7: 2022 | B7: 6 | C7: 彩诗 | D7: 130324 | E7: 257524 | F7: 100 | G7: 5 | H7: 206019.2
A8: 2022 | B8: 7 | C8: 彩诗 | D8: 83576 | E8: 88135.79 | F8: 100 | G8: 5 | H8: 70508.632
A9: 2022 | B9: 8 | C9: 彩诗 | D9: 95972 | E9: 152378.04 | F9: 100 | G9: 5 | H9: 121902.43
A10: 2022 | B10: 9 | C10: 彩诗 | D10: 108712 | E10: 297813.94 | F10: 100 | G10: 5 | H10: 238251.15
A11: 2022 | B11: 10 | C11: 彩诗 | D11: 105428 | E11: 304473.37 | F11: 100 | G11: 5 | H11: 243578.7
A12: 2022 | B12: 11 | C12: 彩诗 | D12: 112848 | E12: 285404.14 | F12: 100 | G12: 5 | H12: 228323.31
A13: 2022 | B13: 12 | C13: 彩诗 | D13: 101956 | E13: 261780.17 | F13: 100 | G13: 5 | H13: 209424.14

Sheet Sheet16
A1: 年份 | B1: 月份 | C1: 项目名 | D1: 临停收入 | E1: 总收入 | F1: 车位数 | G1: 收费标准 | H1: 预测收入
A2: 2022 | B2: 1 | C2: 彩诗 | D2: 115976 | E2: 343526 | F2: 100 | G2: 5 | H2: 274820.8
A3: 2022 | B3: 2 | C3: 彩诗 | D3: 163640 | E3: 409588 | F3: 100 | G3: 5 | H3: 327670.4
A4: 2022 | B4: 3 | C4: 彩诗 | D4: 120392 | E4: 380016 | F4: 100 | G4: 5 | H4: 304012.8
A5: 2022 | B5: 4 | C5: 彩诗 | D5: 95148 | E5: 237098 | F5: 100 | G5: 5 | H5: 189678.4
A6: 2022 | B6: 5 | C6: 彩诗 | D6: 90992 | E6: 210292 | F6: 100 | G6: 5 | H6: 168233.6
A7: 2022 | B7: 6 | C7: 彩诗 | D7: 130324 | E7: 257524 | F7: 100 | G7: 5 | H7: 206019.2
A8: 2022 | B8: 7 | C8: 彩诗 | D8: 83576 | E8: 88135.79 | F8: 100 | G8: 5 | H8: 70508.632
A9: 2022 | B9: 8 | C9: 彩诗 | D9: 95972 | E9: 152378.04 | F9: 100 | G9: 5 | H9: 121902.43
A10: 2022 | B10: 9 | C10: 彩诗 | D10: 108712 | E10: 297813.94 | F10: 100 | G10: 5 | H10: 238251.15
A11: 2022 | B11: 10 | C11: 彩诗 | D11: 105428 | E11: 304473.37 | F11: 100 | G11: 5 | H11: 243578.7
A12: 2022 | B12: 11 | C12: 彩诗 | D12: 112848 | E12: 285404.14 | F12: 100 | G12: 5 | H12: 228323.31
A13: 2022 | B13: 12 | C13: 彩诗 | D13: 101956 | E13: 261780.17 | F13: 100 | G13: 5 | H13: 209424.14
H16: =SUM(表16[预测收入]) -> 2582423.6

Sheet Sheet17
A1: 年份 | B1: 月份 | C1: 项目名 | D1: 临停收入 | E1: 总收入 | F1: 车位数 | G1: 收费标准 | H1: 预测收入
A2: 2022 | B2: 1 | C2: 彩诗 | D2: 115976 | E2: 343526 | F2: 100 | G2: 5 | H2: 274820.8
A3: 2022 | B3: 2 | C3: 彩诗 | D3: 163640 | E3: 409588 | F3: 100 | G3: 5 | H3: 327670.4
A4: 2022 | B4: 3 | C4: 彩诗 | D4: 120392 | E4: 380016 | F4: 100 | G4: 5 | H4: 304012.8
A5: 2022 | B5: 4 | C5: 彩诗 | D5: 95148 | E5: 237098 | F5: 100 | G5: 5 | H5: 189678.4
A6: 2022 | B6: 5 | C6: 彩诗 | D6: 90992 | E6: 210292 | F6: 100 | G6: 5 | H6: 168233.6
A7: 2022 | B7: 6 | C7: 彩诗 | D7: 130324 | E7: 257524 | F7: 100 | G7: 5 | H7: 206019.2
A8: 2022 | B8: 7 | C8: 彩诗 | D8: 83576 | E8: 88135.79 | F8: 100 | G8: 5 | H8: 70508.632
A9: 2022 | B9: 8 | C9: 彩诗 | D9: 95972 | E9: 152378.04 | F9: 100 | G9: 5 | H9: 121902.43
A10: 2022 | B10: 9 | C10: 彩诗 | D10: 108712 | E10: 297813.94 | F10: 100 | G10: 5 | H10: 238251.15
A11: 2022 | B11: 10 | C11: 彩诗 | D11: 105428 | E11: 304473.37 | F11: 100 | G11: 5 | H11: 243578.7
A12: 2022 | B12: 11 | C12: 彩诗 | D12: 112848 | E12: 285404.14 | F12: 100 | G12: 5 | H12: 228323.31
A13: 2022 | B13: 12 | C13: 彩诗 | D13: 101956 | E13: 261780.17 | F13: 100 | G13: 5 | H13: 209424.14

Sheet Sheet18
A1: 年份 | B1: 月份 | C1: 项目名 | D1: 临停收入 | E1: 总收入 | F1: 车位数 | G1: 收费标准 | H1: 预测收入
A2: 2022 | B2: 1 | C2: 彩诗 | D2: 115976 | E2: 343526 | F2: 100 | G2: 5 | H2: 274820.8
A3: 2022 | B3: 2 | C3: 彩诗 | D3: 163640 | E3: 409588 | F3: 100 | G3: 5 | H3: 327670.4
A4: 2022 | B4: 3 | C4: 彩诗 | D4: 120392 | E4: 380016 | F4: 100 | G4: 5 | H4: 304012.8
A5: 2022 | B5: 4 | C5: 彩诗 | D5: 95148 | E5: 237098 | F5: 100 | G5: 5 | H5: 189678.4
A6: 2022 | B6: 5 | C6: 彩诗 | D6: 90992 | E6: 210292 | F6: 100 | G6: 5 | H6: 168233.6
A7: 2022 | B7: 6 | C7: 彩诗 | D7: 130324 | E7: 257524 | F7: 100 | G7: 5 | H7: 206019.2
A8: 2022 | B8: 7 | C8: 彩诗 | D8: 83576 | E8: 88135.79 | F8: 100 | G8: 5 | H8: 70508.632
A9: 2022 | B9: 8 | C9: 彩诗 | D9: 95972 | E9: 152378.04 | F9: 100 | G9: 5 | H9: 121902.43
A10: 2022 | B10: 9 | C10: 彩诗 | D10: 108712 | E10: 297813.94 | F10: 100 | G10: 5 | H10: 238251.15
A11: 2022 | B11: 10 | C11: 彩诗 | D11: 105428 | E11: 304473.37 | F11: 100 | G11: 5 | H11: 243578.7
A12: 2022 | B12: 11 | C12: 彩诗 | D12: 112848 | E12: 285404.14 | F12: 100 | G12: 5 | H12: 228323.31
A13: 2022 | B13: 12 | C13: 彩诗 | D13: 101956 | E13: 261780.17 | F13: 100 | G13: 5 | H13: 209424.14

Sheet Sheet2
A1: 年份 | B1: 月份 | C1: 项目名 | D1: 临停收入 | E1: 总收入 | F1: 车位数 | G1: 收费标准 | H1: 预测收入
A2: 2022 | B2: 1 | C2: 彩诗 | D2: 115976 | E2: 343526 | F2: 100 | G2: 5 | H2: 687.052
A3: 2022 | B3: 2 | C3: 彩诗 | D3: 163640 | E3: 409588 | F3: 100 | G3: 5 | H3: 819.176
A4: 2022 | B4: 3 | C4: 彩诗 | D4: 120392 | E4: 380016 | F4: 100 | G4: 5 | H4: 760.032
A5: 2022 | B5: 4 | C5: 彩诗 | D5: 95148 | E5: 237098 | F5: 100 | G5: 5 | H5: 474.196
A6: 2022 | B6: 5 | C6: 彩诗 | D6: 90992 | E6: 210292 | F6: 100 | G6: 5 | H6: 420.584
A7: 2022 | B7: 6 | C7: 彩诗 | D7: 130324 | E7: 257524 | F7: 100 | G7: 5 | H7: 515.048
A8: 2022 | B8: 7 | C8: 彩诗 | D8: 83576 | E8: 88135.79 | F8: 100 | G8: 5 | H8: 176.27158
A9: 2022 | B9: 8 | C9: 彩诗 | D9: 95972 | E9: 152378.04 | F9: 100 | G9: 5 | H9: 304.75608
A10: 2022 | B10: 9 | C10: 彩诗 | D10: 108712 | E10: 297813.94 | F10: 100 | G10: 5 | H10: 595.62788
A11: 2022 | B11: 10 | C11: 彩诗 | D11: 105428 | E11: 304473.37 | F11: 100 | G11: 5 | H11: 608.94674
A12: 2022 | B12: 11 | C12: 彩诗 | D12: 112848 | E12: 285404.14 | F12: 100 | G12: 5 | H12: 570.80828
A13: 2022 | B13: 12 | C13: 彩诗 | D13: 101956 | E13: 261780.17 | F13: 100 | G13: 5 | H13: 523.56034
... A49: 2022 | B49: 12 | C49: 东河路8号 | D49: 335460 | E49: 337781.54 | F49: 100 | G49: 5 | H49: 675.56308
A50: 2022 | B50: 1 | C50: 翰林花园 | E50: 11950 | F50: 100 | G50: 5 | H50: 23.9
A51: 2022 | B51: 2 | C51: 翰林花园 | E51: 11950 | F51: 100 | G51: 5 | H51: 23.9
A52: 2022 | B52: 3 | C52: 翰林花园 | E52: 11950 | F52: 100 | G52: 5 | H52: 23.9
A53: 2022 | B53: 4 | C53: 翰林花园 | E53: 11650 | F53: 100 | G53: 5 | H53: 23.3
A54: 2022 | B54: 5 | C54: 翰林花园 | E54: 11950 | F54: 100 | G54: 5 | H54: 23.9
A55: 2022 | B55: 6 | C55: 翰林花园 | E55: 12250 | F55: 100 | G55: 5 | H55: 24.5
A56: 2022 | B56: 7 | C56: 翰林花园 | D56: 28200 | E56: 31216.13 | F56: 100 | G56: 5 | H56: 62.43226
A57: 2022 | B57: 8 | C57: 翰林花园 | E57: 11902.5 | F57: 100 | G57: 5 | H57: 23.805
A58: 2022 | B58: 9 | C58: 翰林花园 | E58: 11523.98 | F58: 100 | G58: 5 | H58: 23.04796
A59: 2022 | B59: 10 | C59: 翰林花园 | E59: 10802.64 | F59: 100 | G59: 5 | H59: 21.60528
A60: 2022 | B60: 11 | C60: 翰林花园 | E60: 11616.9 | F60: 100 | G60: 5 | H60: 23.2338
A61: 2022 | B61: 12 | C61: 翰林花园 | E61: 13314.29 | F61: 100 | G61: 5 | H61: 26.62858
A62: 2022 | B62: 1 | C62: 市肿瘤医院 | D62: 52845 | E62: 72345 | F62: 100 | G62: 5 | H62: 144.69
A63: 2022 | B63: 2 | C63: 市肿瘤医院 | D63: 84210 | E63: 106710 | F63: 100 | G63: 5 | H63: 213.42
A64: 2022 | B64: 3 | C64: 市肿瘤医院 | D64: 69425 | E64: 91925 | F64: 100 | G64: 5 | H64: 183.85
A65: 2022 | B65: 4 | C65: 市肿瘤医院 | D65: 82730 | E65: 104230 | F65: 100 | G65: 5 | H65: 208.46
A66: 2022 | B66: 5 | C66: 市肿瘤医院 | D66: 80540 | E66: 101540 | F66: 100 | G66: 5 | H66: 203.08
A67: 2022 | B67: 6 | C67: 市肿瘤医院 | D67: 91600 | E67: 116100 | F67: 100 | G67: 5 | H67: 232.2
A68: 2022 | B68: 7 | C68: 市肿瘤医院 | D68: 65055 | E68: 68948.11 | F68: 100 | G68: 5 | H68: 137.89622
A69: 2022 | B69: 8 | C69: 市肿瘤医院 | D69: 77400 | E69: 100640.03 | F69: 100 | G69: 5 | H69: 201.28006
A70: 2022 | B70: 9 | C70: 市肿瘤医院 | D70: 79400 | E70: 102655.04 | F70: 100 | G70: 5 | H70: 205.31008
A71: 2022 | B71: 10 | C71: 市肿瘤医院 | D71: 79065 | E71: 101379.24 | F71: 100 | G71: 5 | H71: 202.75848
A72: 2022 | B72: 11 | C72: 市肿瘤医院 | D72: 75925 | E72: 102779.16 | F72: 100 | G72: 5 | H72: 205.55832
A73: 2022 | B73: 12 | C73: 市肿瘤医院 | D73: 83995 | E73: 117784.36 | F73: 100 | G73: 5 | H73: 235.56872
... A157: 2022 | B157: 12 | C157: 纽约纽约 | D157: 4550 | E157: 4961.61 | F157: 100 | G157: 5 | H157: 9.92322

Sheet Sheet19
A1: 年份 | B1: 月份 | C1: 项目名 | D1: 临停收入 | E1: 总收入 | F1: 车位数 | G1: 收费标准 | H1: 预测收入
A2: 2022 | B2: 1 | C2: 彩诗（办公+商业） | D2: 115976 | E2: 343526 | F2: 181 | G2: 4 | H2: 5409111
A3: 2022 | B3: 2 | C3: 彩诗（办公+商业） | D3: 163640 | E3: 409588 | F3: 181 | G3: 4 | H3: 6449313.8
A4: 2022 | B4: 3 | C4: 彩诗（办公+商业） | D4: 120392 | E4: 380016 | F4: 181 | G4: 4 | H4: 5983677.3
A5: 2022 | B5: 4 | C5: 彩诗（办公+商业） | D5: 95148 | E5: 237098 | F5: 181 | G5: 4 | H5: 3733311
A6: 2022 | B6: 5 | C6: 彩诗（办公+商业） | D6: 90992 | E6: 210292 | F6: 181 | G6: 4 | H6: 3311227.6
A7: 2022 | B7: 6 | C7: 彩诗（办公+商业） | D7: 130324 | E7: 257524 | F7: 181 | G7: 4 | H7: 4054935.9
A8: 2022 | B8: 7 | C8: 彩诗（办公+商业） | D8: 83576 | E8: 88135.79 | F8: 181 | G8: 4 | H8: 1387773.5
A9: 2022 | B9: 8 | C9: 彩诗（办公+商业） | D9: 95972 | E9: 152378.04 | F9: 181 | G9: 4 | H9: 2399322.7
A10: 2022 | B10: 9 | C10: 彩诗（办公+商业） | D10: 108712 | E10: 297813.94 | F10: 181 | G10: 4 | H10: 4689335.5
A11: 2022 | B11: 10 | C11: 彩诗（办公+商业） | D11: 105428 | E11: 304473.37 | F11: 181 | G11: 4 | H11: 4794193.9
A12: 2022 | B12: 11 | C12: 彩诗（办公+商业） | D12: 112848 | E12: 285404.14 | F12: 181 | G12: 4 | H12: 4493932.6
A13: 2022 | B13: 12 | C13: 彩诗（办公+商业） | D13: 101956 | E13: 261780.17 | F13: 181 | G13: 4 | H13: 4121953
... A133: 2022 | B133: 12 | C133: 纽约纽约（商业+小区） | D133: 4550 | E133: 4961.61 | F133: 53 | G133: 5 | H133: 213442.85
A134: 2022 | B134: 1 | C134: 宁波冠宇（商业） | E134: 27011.95 | F134: 190 | G134: 5 | H134: 324143.4
A135: 2022 | B135: 2 | C135: 宁波冠宇（商业） | E135: 47269.67 | F135: 190 | G135: 5 | H135: 567236.04
A136: 2022 | B136: 3 | C136: 宁波冠宇（商业） | E136: 38726.24 | F136: 190 | G136: 5 | H136: 464714.88
A137: 2022 | B137: 4 | C137: 宁波冠宇（商业） | E137: 27981.1 | F137: 190 | G137: 5 | H137: 335773.2
A138: 2022 | B138: 5 | C138: 宁波冠宇（商业） | E138: 35965.93 | F138: 190 | G138: 5 | H138: 431591.16
A139: 2022 | B139: 6 | C139: 宁波冠宇（商业） | E139: 36396 | F139: 190 | G139: 5 | H139: 436752
A140: 2022 | B140: 7 | C140: 宁波冠宇（商业） | E140: 31808.49 | F140: 190 | G140: 5 | H140: 381701.88
A141: 2022 | B141: 8 | C141: 宁波冠宇（商业） | E141: 30712.7 | F141: 190 | G141: 5 | H141: 368552.4
A142: 2022 | B142: 9 | C142: 宁波冠宇（商业） | E142: 33409.86 | F142: 190 | G142: 5 | H142: 400918.32
A143: 2022 | B143: 10 | C143: 宁波冠宇（商业） | E143: 33987.74 | F143: 190 | G143: 5 | H143: 407852.88
A144: 2022 | B144: 11 | C144: 宁波冠宇（商业） | E144: 42640.43 | F144: 190 | G144: 5 | H144: 511685.16
A145: 2022 | B145: 12 | C145: 宁波冠宇（商业） | E145: 46433.93 | F145: 190 | G145: 5 | H145: 557207.16

Sheet Sheet20
A1: 年份 | B1: 月份 | C1: 项目名 | D1: 临停收入 | E1: 总收入 | F1: 车位数 | G1: 收费标准 | H1: 预测收入
A2: 2022 | B2: 1 | C2: 杭州市肿瘤（医院） | D2: 52845 | E2: 72345 | F2: 111 | G2: 5 | H2: 1486005.4

Sheet Sheet21
A1: 年份 | B1: 月份 | C1: 项目名 | D1: 临停收入 | E1: 总收入 | F1: 车位数 | G1: 收费标准 | H1: 预测收入
A2: 2022 | B2: 1 | C2: 杭州市肿瘤（医院） | D2: 52845 | E2: 72345 | F2: 111 | G2: 5 | H2: 1486005.4

Sheet Sheet22
A1: 年份 | B1: 月份 | C1: 项目名 | D1: 临停收入 | E1: 总收入 | F1: 车位数 | G1: 收费标准 | H1: 预测收入
A2: 2022 | B2: 1 | C2: 杭州市肿瘤（医院） | D2: 52845 | E2: 72345 | F2: 111 | G2: 5 | H2: 1486005.4

Sheet Sheet23
A1: 年份 | B1: 月份 | C1: 项目名 | D1: 临停收入 | E1: 总收入 | F1: 车位数 | G1: 收费标准 | H1: 预测收入
A2: 2022 | B2: 12 | C2: 安吉城市级（停车场） | E2: 116184 | F2: 1120 | G2: 3 | H2: 3941.9571
A3: 2022 | B3: 11 | C3: 安吉城市级（停车场） | E3: 181774 | F3: 1120 | G3: 3 | H3: 6167.3321
A4: 2022 | B4: 10 | C4: 安吉城市级（停车场） | E4: 199461 | F4: 1120 | G4: 3 | H4: 6767.4268
A5: 2022 | B5: 9 | C5: 安吉城市级（停车场） | E5: 191597 | F5: 1120 | G5: 3 | H5: 6500.6125
A6: 2022 | B6: 8 | C6: 安吉城市级（停车场） | E6: 209742 | F6: 1120 | G6: 3 | H6: 7116.2464
A7: 2022 | B7: 7 | C7: 安吉城市级（停车场） | E7: 210065 | F7: 1120 | G7: 3 | H7: 7127.2054
A8: 2022 | B8: 6 | C8: 安吉城市级（停车场） | E8: 193294 | F8: 1120 | G8: 3 | H8: 6558.1893
A9: 2022 | B9: 5 | C9: 安吉城市级（停车场） | E9: 213595 | F9: 1120 | G9: 3 | H9: 7246.9732
A10: 2022 | B10: 4 | C10: 安吉城市级（停车场） | E10: 164290 | F10: 1120 | G10: 3 | H10: 5574.125
A11: 2022 | B11: 3 | C11: 安吉城市级（停车场） | E11: 168580 | F11: 1120 | G11: 3 | H11: 5719.6786
A12: 2022 | B12: 2 | C12: 安吉城市级（停车场） | E12: 145815 | F12: 1120 | G12: 3 | H12: 4947.2946
A13: 2022 | B13: 1 | C13: 安吉城市级（停车场） | E13: 256954 | F13: 1120 | G13: 3 | H13: 8718.0821

Sheet Sheet24
A1: 年份 | B1: 月份 | C1: 项目名 | D1: 临停收入 | E1: 总收入 | F1: 车位数 | G1: 收费标准 | H1: 预测收入
A2: 2022 | B2: 6 | C2: 彩诗（公共+办公） | D2: 130324 | E2: 257524 | F2: 181 | G2: 4 | H2: 40549.359

Sheet Sheet25
A1: 年份 | B1: 月份 | C1: 项目名 | D1: 临停收入 | E1: 总收入 | F1: 车位数 | G1: 收费标准 | H1: 预测收入
A2: 2022 | B2: 1 | C2: 上海胸科（医院） | D2: 127304.93 | E2: 127304.93 | F2: 166 | G2: 8 | H2: 10928.285

Sheet Sheet26
A1: 年份 | B1: 月份 | C1: 项目名 | D1: 临停收入 | E1: 总收入 | F1: 车位数 | G1: 收费标准 | H1: 预测收入
A2: 2022 | B2: 1 | C2: 上海胸科（医院） | D2: 127304.93 | E2: 127304.93 | F2: 166 | G2: 8 | H2: 10928.285
A3: 2022 | B3: 2 | C3: 上海胸科（医院） | D3: 162111.54 | E3: 162111.54 | F3: 166 | G3: 8 | H3: 13916.201
A4: 2022 | B4: 3 | C4: 上海胸科（医院） | D4: 115922.97 | E4: 115922.97 | F4: 166 | G4: 8 | H4: 9951.2188
A5: 2022 | B5: 4 | C5: 上海胸科（医院） | D5: 15001.96 | E5: 15001.96 | F5: 166 | G5: 8 | H5: 1287.8189
A6: 2022 | B6: 5 | C6: 上海胸科（医院） | D6: 8747 | E6: 8747 | F6: 166 | G6: 8 | H6: 750.87199
A7: 2022 | B7: 6 | C7: 上海胸科（医院） | D7: 102623 | E7: 102623 | F7: 166 | G7: 8 | H7: 8809.5045
A8: 2022 | B8: 7 | C8: 上海胸科（医院） | D8: 141328.8 | E8: 141328.8 | F8: 166 | G8: 8 | H8: 12132.141
A9: 2022 | B9: 8 | C9: 上海胸科（医院） | D9: 159199.92 | E9: 161941.33 | F9: 166 | G9: 8 | H9: 13901.59
A10: 2022 | B10: 9 | C10: 上海胸科（医院） | D10: 119886.05 | E10: 126184.95 | F10: 166 | G10: 8 | H10: 10832.142
A11: 2022 | B11: 10 | C11: 上海胸科（医院） | D11: 124064.02 | E11: 124491.63 | F11: 166 | G11: 8 | H11: 10686.781
A12: 2022 | B12: 11 | C12: 上海胸科（医院） | D12: 119273.36 | E12: 123982.26 | F12: 166 | G12: 8 | H12: 10643.055
A13: 2022 | B13: 12 | C13: 上海胸科（医院） | D13: 46367.2 | E13: 51687.26 | F13: 166 | G13: 8 | H13: 4437.0088

Sheet Sheet27
A1: 年份 | B1: 月份 | C1: 项目名 | D1: 临停收入 | E1: 总收入 | F1: 车位数 | G1: 收费标准 | H1: 预测收入
A2: 2022 | B2: 1 | C2: 杭州市肿瘤（医院） | D2: 52845 | E2: 72345 | F2: 111 | G2: 5 | H2: 14860.054

Sheet Sheet28
A1: 年份 | B1: 月份 | C1: 项目名 | D1: 临停收入 | E1: 总收入 | F1: 车位数 | G1: 收费标准 | H1: 预测收入
A2: 2022 | B2: 5 | C2: 杭州市肿瘤（医院） | D2: 80540 | E2: 101540 | F2: 111 | G2: 5 | H2: 20856.865

Sheet Sheet29
A1: 年份 | B1: 月份 | C1: 项目名 | D1: 临停收入 | E1: 总收入 | F1: 车位数 | G1: 收费标准 | H1: 预测收入
A2: 2022 | B2: 1 | C2: 彩诗（公共+办公） | D2: 115976 | E2: 343526 | F2: 181 | G2: 4 | H2: 54091.11

Sheet Sheet30
A1: 年份 | B1: 月份 | C1: 项目名 | D1: 临停收入 | E1: 总收入 | F1: 车位数 | G1: 收费标准 | H1: 预测收入
A2: 2022 | B2: 3 | C2: 彩诗（公共+办公） | D2: 120392 | E2: 380016 | F2: 181 | G2: 4 | H2: 59836.773

Sheet Sheet31
A1: 年份 | B1: 月份 | C1: 项目名 | D1: 临停收入 | E1: 总收入 | F1: 车位数 | G1: 收费标准 | H1: 预测收入
A2: 2022 | B2: 11 | C2: 彩诗（公共+办公） | D2: 112848 | E2: 285404.14 | F2: 181 | G2: 4 | H2: 44939.326

Sheet 透视表（刷新）
A3: 行标签 | B3: 求和项:测算项目预测收入 | C3: 左 侧 表 格 点 击 刷 新 | G3: 求和项:测算项目预测收入
A4: 1 | B4: 201856.24 | G4: 4004791.7
A5: 2 | B5: 340968.94
A6: 3 | B6: 302714.12
A7: 4 | B7: 327380.75
A8: 5 | B8: 330171.44
A9: 6 | B9: 439495.01
A10: 7 | B10: 317345.35
A11: 8 | B11: 385148.21
A12: 9 | B12: 348015.14
A13: 10 | B13: 351657.22
A14: 11 | B14: 343716.82
A15: 12 | B15: 316322.48
A16: 总计 | B16: 4004791.7
A21: 总收入 | B21: =GETPIVOTDATA("测算项目预测收入",$G$3)/10000 -> 400.47917
A24: 1 | B24: =GETPIVOTDATA("测算项目预测收入",$A$3,"月份",1)/10000 -> 20.185624
A25: 2 | B25: =GETPIVOTDATA("测算项目预测收入",$A$3,"月份",2)/10000 -> 34.096894
A26: 3 | B26: =GETPIVOTDATA("测算项目预测收入",$A$3,"月份",3)/10000 -> 30.271412
A27: 4 | B27: =GETPIVOTDATA("测算项目预测收入",$A$3,"月份",4)/10000 -> 32.738075
A28: 5 | B28: =GETPIVOTDATA("测算项目预测收入",$A$3,"月份",5)/10000 -> 33.017144
A29: 6 | B29: =GETPIVOTDATA("测算项目预测收入",$A$3,"月份",6)/10000 -> 43.949501
A30: 7 | B30: =GETPIVOTDATA("测算项目预测收入",$A$3,"月份",7)/10000 -> 31.734535
A31: 8 | B31: =GETPIVOTDATA("测算项目预测收入",$A$3,"月份",8)/10000 -> 38.514821
A32: 9 | B32: =GETPIVOTDATA("测算项目预测收入",$A$3,"月份",9)/10000 -> 34.801514
A33: 10 | B33: =GETPIVOTDATA("测算项目预测收入",$A$3,"月份",10)/10000 -> 35.165722
A34: 11 | B34: =GETPIVOTDATA("测算项目预测收入",$A$3,"月份",11)/10000 -> 34.371682
A35: 12 | B35: =GETPIVOTDATA("测算项目预测收入",$A$3,"月份",12)/10000 -> 31.632248
A38: 单车位收入 | B38: =B21*10000/项目看板!$C$38/365 -> 27.56792

Sheet Sheet5
A1: 年份 | B1: 月份 | C1: 项目区域 | D1: 项目经理 | E1: 项目名 | F1: 临停收入 | G1: 代金券收入 | H1: 包月收入 | I1: 总收入 | J1: 去年总收入 | K1: 增长率
A2: 2021 | B2: 12 | C2: 杭州 | D2: 刘东风 | E2: 彩诗 | F2: 183737 | G2: 2128 | H2: 124436 | I2: 310301 | J2: 273217 | K2: -0.11950977
A3: 2021 | B3: 11 | C3: 杭州 | D3: 刘东风 | E3: 彩诗 | F3: 151082 | G3: 11920 | H3: 63336 | I3: 226338 | J3: 248336 | K3: 0.097190927
A4: 2021 | B4: 10 | C4: 杭州 | D4: 刘东风 | E4: 彩诗 | F4: 137767 | G4: 20300 | H4: 61586 | I4: 219653 | J4: 229148 | K4: 0.043227272
A5: 2021 | B5: 9 | C5: 杭州 | D5: 刘东风 | E5: 彩诗 | F5: 146347 | G5: 4208 | H5: 89444.26 | I5: 239999.26 | J5: 198597 | K5: -0.17250995
A6: 2021 | B6: 8 | C6: 杭州 | D6: 刘东风 | E6: 彩诗 | F6: 139933 | G6: 20512 | H6: 91344.34 | I6: 251789.34 | J6: 182679 | K6: -0.27447683
A7: 2021 | B7: 7 | C7: 杭州 | D7: 刘东风 | E7: 彩诗 | F7: 108771 | G7: 4888 | H7: 87744.34 | I7: 201403.34 | J7: 165680 | K7: -0.17737213
A8: 2021 | B8: 6 | C8: 杭州 | D8: 刘东风 | E8: 彩诗 | F8: 151070 | G8: 5440 | H8: 145944.34 | I8: 302454.34 | J8: 219046 | K8: -0.27577168
A9: 2021 | B9: 5 | C9: 杭州 | D9: 刘东风 | E9: 彩诗 | F9: 125915 | G9: 16256 | H9: 144094.34 | I9: 286265.34 | J9: 179778 | K9: -0.37198824
A10: 2021 | B10: 4 | C10: 杭州 | D10: 刘东风 | E10: 彩诗 | F10: 141445 | G10: 17176 | H10: 121044.34 | I10: 279665.34 | J10: 162372 | K10: -0.41940607
A11: 2021 | B11: 3 | C11: 杭州 | D11: 刘东风 | E11: 彩诗 | F11: 131270 | G11: 14000 | H11: 138994.34 | I11: 284264.34 | J11: 113048 | K11: -0.60231382
A12: 2021 | B12: 2 | C12: 杭州 | D12: 刘东风 | E12: 彩诗 | F12: 124146.05 | G12: 12000 | H12: 171327.6 | I12: 307473.65 | J12: 78002 | K12: -0.74631322
A13: 2021 | B13: 1 | C13: 杭州 | D13: 刘东风 | E13: 彩诗 | F13: 111050 | G13: 6000 | H13: 87577.68 | I13: 204627.68 | J13: 159272 | K13: -0.22164978

Sheet 项目看板
W31: =(NPER(N44/12,-1*(('透视表（刷新）'!G4*(1-L44)*P44-R40)/12)*Q44,R37)/12)*R44 -> 4.9297412
A35: 请在下方输入测算信息（停车场收入可单独测算）
A36: 收 入 数 据 | C36: 车位数 （个） | E36: 收费标准 （元/小时） | G36: 收入系数调整 （建议调整范围 0.5~1.5） | I36: 投 资 数 据 | K36: 项目 投建 | L36: 机械库 | M36: 土建 | N36: 智能系统 | O36: 土地出让金 | P36: 其它费用 | Q36: / | R36: 投建合计成本
L37: 10000000 | R37: =SUM(L37:Q38) -> 10000000
C38: 398 | E38: 4 | G38: 1
K39: 项目 运营 | L39: 管理人员 | M39: 电费 | N39: 维保 | O39: 年检 | P39: 大修 | Q39: 其他费用 | R39: 运营合计成本
L40: 480000 | M40: 67500 | N40: 90000 | O40: 18750 | Q40: 800000 | R40: =SUM(L40:Q41) -> 1456250
K42: 其它 参数 | L42: 经营税费 | N42: 折现率 | P42: 收益分成比 | R42: 上浮率
P43: 收入分成 | Q43: 收益分成
L44: 0.05 | N44: 0.06 | P44: 1 | Q44: 1 | R44: 1
A45: 备注 | C45: 调整收入数据后，需在透视表中选择刷新
